<?xml version="1.0" encoding="UTF-8"?>
<!-- Generated by org.testng.reporters.JUnitReportReporter -->
<testsuite hostname="DESKTOP-OU80H79" failures="2" tests="13" name="com.app.test.Fail_Test_Capture" time="0.200" errors="0" timestamp="2023-10-07T11:15:34 IST" skipped="10">
  <testcase classname="com.app.test.Fail_Test_Capture" name="test2" time="0.066"/>
  <system-out/>
  <testcase classname="com.app.test.Fail_Test_Capture" name="test3" time="0.061">
    <skipped/>
  </testcase> <!-- test3 -->
  <system-out/>
  <testcase classname="com.app.test.Fail_Test_Capture" name="test4" time="0.002">
    <skipped/>
  </testcase> <!-- test4 -->
  <system-out/>
  <testcase classname="com.app.test.Fail_Test_Capture" name="test3" time="0.008">
    <skipped/>
  </testcase> <!-- test3 -->
  <system-out/>
  <testcase classname="com.app.test.Fail_Test_Capture" name="test3" time="0.011">
    <skipped/>
  </testcase> <!-- test3 -->
  <system-out/>
  <testcase classname="com.app.test.Fail_Test_Capture" name="test4" time="0.008">
    <skipped/>
  </testcase> <!-- test4 -->
  <system-out/>
  <testcase classname="com.app.test.Fail_Test_Capture" name="test4" time="0.005">
    <skipped/>
  </testcase> <!-- test4 -->
  <system-out/>
  <testcase classname="com.app.test.Fail_Test_Capture" name="test4" time="0.004">
    <skipped/>
  </testcase> <!-- test4 -->
  <system-out/>
  <testcase classname="com.app.test.Fail_Test_Capture" name="test3" time="0.005">
    <failure message="expected [Aite] but found [Aiite]" type="java.lang.AssertionError">
      <![CDATA[java.lang.AssertionError: expected [Aite] but found [Aiite]
at org.testng.Assert.fail(Assert.java:110)
at org.testng.Assert.failNotEquals(Assert.java:1577)
at org.testng.Assert.assertEqualsImpl(Assert.java:149)
at org.testng.Assert.assertEquals(Assert.java:131)
at org.testng.Assert.assertEquals(Assert.java:655)
at org.testng.Assert.assertEquals(Assert.java:665)
at com.app.test.Fail_Test_Capture.test3(Fail_Test_Capture.java:25)
at java.base/jdk.internal.reflect.NativeMethodAccessorImpl.invoke0(Native Method)
at java.base/jdk.internal.reflect.NativeMethodAccessorImpl.invoke(NativeMethodAccessorImpl.java:62)
at java.base/jdk.internal.reflect.DelegatingMethodAccessorImpl.invoke(DelegatingMethodAccessorImpl.java:43)
at java.base/java.lang.reflect.Method.invoke(Method.java:566)
at org.testng.internal.invokers.MethodInvocationHelper.invokeMethod(MethodInvocationHelper.java:139)
at org.testng.internal.invokers.TestInvoker.invokeMethod(TestInvoker.java:677)
at org.testng.internal.invokers.TestInvoker.retryFailed(TestInvoker.java:263)
at org.testng.internal.invokers.MethodRunner.runInSequence(MethodRunner.java:62)
at org.testng.internal.invokers.TestInvoker$MethodInvocationAgent.invoke(TestInvoker.java:969)
at org.testng.internal.invokers.TestInvoker.invokeTestMethods(TestInvoker.java:194)
at org.testng.internal.invokers.TestMethodWorker.invokeTestMethods(TestMethodWorker.java:148)
at org.testng.internal.invokers.TestMethodWorker.run(TestMethodWorker.java:128)
at java.base/java.util.ArrayList.forEach(ArrayList.java:1541)
at org.testng.TestRunner.privateRun(TestRunner.java:829)
at org.testng.TestRunner.run(TestRunner.java:602)
at org.testng.SuiteRunner.runTest(SuiteRunner.java:437)
at org.testng.SuiteRunner.runSequentially(SuiteRunner.java:431)
at org.testng.SuiteRunner.privateRun(SuiteRunner.java:391)
at org.testng.SuiteRunner.run(SuiteRunner.java:330)
at org.testng.SuiteRunnerWorker.runSuite(SuiteRunnerWorker.java:52)
at org.testng.SuiteRunnerWorker.run(SuiteRunnerWorker.java:95)
at org.testng.TestNG.runSuitesSequentially(TestNG.java:1256)
at org.testng.TestNG.runSuitesLocally(TestNG.java:1176)
at org.testng.TestNG.runSuites(TestNG.java:1099)
at org.testng.TestNG.run(TestNG.java:1067)
at org.testng.remote.AbstractRemoteTestNG.run(AbstractRemoteTestNG.java:115)
at org.testng.remote.RemoteTestNG.initAndRun(RemoteTestNG.java:251)
at org.testng.remote.RemoteTestNG.main(RemoteTestNG.java:77)
]]>
    </failure>
  </testcase> <!-- test3 -->
  <system-out/>
  <testcase classname="com.app.test.Fail_Test_Capture" name="test3" time="0.016">
    <skipped/>
  </testcase> <!-- test3 -->
  <system-out/>
  <testcase classname="com.app.test.Fail_Test_Capture" name="test3" time="0.007">
    <skipped/>
  </testcase> <!-- test3 -->
  <system-out/>
  <testcase classname="com.app.test.Fail_Test_Capture" name="test4" time="0.003">
    <failure message="expected [Aite] but found [Aiite]" type="java.lang.AssertionError">
      <![CDATA[java.lang.AssertionError: expected [Aite] but found [Aiite]
at org.testng.Assert.fail(Assert.java:110)
at org.testng.Assert.failNotEquals(Assert.java:1577)
at org.testng.Assert.assertEqualsImpl(Assert.java:149)
at org.testng.Assert.assertEquals(Assert.java:131)
at org.testng.Assert.assertEquals(Assert.java:655)
at org.testng.Assert.assertEquals(Assert.java:665)
at com.app.test.Fail_Test_Capture.test4(Fail_Test_Capture.java:32)
at java.base/jdk.internal.reflect.NativeMethodAccessorImpl.invoke0(Native Method)
at java.base/jdk.internal.reflect.NativeMethodAccessorImpl.invoke(NativeMethodAccessorImpl.java:62)
at java.base/jdk.internal.reflect.DelegatingMethodAccessorImpl.invoke(DelegatingMethodAccessorImpl.java:43)
at java.base/java.lang.reflect.Method.invoke(Method.java:566)
at org.testng.internal.invokers.MethodInvocationHelper.invokeMethod(MethodInvocationHelper.java:139)
at org.testng.internal.invokers.TestInvoker.invokeMethod(TestInvoker.java:677)
at org.testng.internal.invokers.TestInvoker.retryFailed(TestInvoker.java:263)
at org.testng.internal.invokers.MethodRunner.runInSequence(MethodRunner.java:62)
at org.testng.internal.invokers.TestInvoker$MethodInvocationAgent.invoke(TestInvoker.java:969)
at org.testng.internal.invokers.TestInvoker.invokeTestMethods(TestInvoker.java:194)
at org.testng.internal.invokers.TestMethodWorker.invokeTestMethods(TestMethodWorker.java:148)
at org.testng.internal.invokers.TestMethodWorker.run(TestMethodWorker.java:128)
at java.base/java.util.ArrayList.forEach(ArrayList.java:1541)
at org.testng.TestRunner.privateRun(TestRunner.java:829)
at org.testng.TestRunner.run(TestRunner.java:602)
at org.testng.SuiteRunner.runTest(SuiteRunner.java:437)
at org.testng.SuiteRunner.runSequentially(SuiteRunner.java:431)
at org.testng.SuiteRunner.privateRun(SuiteRunner.java:391)
at org.testng.SuiteRunner.run(SuiteRunner.java:330)
at org.testng.SuiteRunnerWorker.runSuite(SuiteRunnerWorker.java:52)
at org.testng.SuiteRunnerWorker.run(SuiteRunnerWorker.java:95)
at org.testng.TestNG.runSuitesSequentially(TestNG.java:1256)
at org.testng.TestNG.runSuitesLocally(TestNG.java:1176)
at org.testng.TestNG.runSuites(TestNG.java:1099)
at org.testng.TestNG.run(TestNG.java:1067)
at org.testng.remote.AbstractRemoteTestNG.run(AbstractRemoteTestNG.java:115)
at org.testng.remote.RemoteTestNG.initAndRun(RemoteTestNG.java:251)
at org.testng.remote.RemoteTestNG.main(RemoteTestNG.java:77)
]]>
    </failure>
  </testcase> <!-- test4 -->
  <system-out/>
  <testcase classname="com.app.test.Fail_Test_Capture" name="test4" time="0.004">
    <skipped/>
  </testcase> <!-- test4 -->
  <system-out/>
</testsuite> <!-- com.app.test.Fail_Test_Capture -->
